Traceback (most recent call last):
  File "/mnt/Client/Ctan682hia6krkvbghfcwq2mtmmnzsxa/ctactafmnaa6edh5dendtkiwzdi5fosy/.venv/lib/python3.10/site-packages/torch/__init__.py", line 174, in _load_global_deps
    ctypes.CDLL(lib_path, mode=ctypes.RTLD_GLOBAL)
  File "/usr/lib/python3.10/ctypes/__init__.py", line 374, in __init__
    self._handle = _dlopen(self._name, mode)
OSError: libcufft.so.11: cannot open shared object file: No such file or directory

During handling of the above exception, another exception occurred:

Traceback (most recent call last):
  File "/mnt/Client/Ctan682hia6krkvbghfcwq2mtmmnzsxa/ctactafmnaa6edh5dendtkiwzdi5fosy/.venv/bin/torchrun", line 5, in <module>
    from torch.distributed.run import main
  File "/mnt/Client/Ctan682hia6krkvbghfcwq2mtmmnzsxa/ctactafmnaa6edh5dendtkiwzdi5fosy/.venv/lib/python3.10/site-packages/torch/__init__.py", line 234, in <module>
    _load_global_deps()
  File "/mnt/Client/Ctan682hia6krkvbghfcwq2mtmmnzsxa/ctactafmnaa6edh5dendtkiwzdi5fosy/.venv/lib/python3.10/site-packages/torch/__init__.py", line 196, in _load_global_deps
    ctypes.CDLL(lib_path, mode=ctypes.RTLD_GLOBAL)
  File "/usr/lib/python3.10/ctypes/__init__.py", line 374, in __init__
    self._handle = _dlopen(self._name, mode)
OSError: libcufft.so.11: cannot open shared object file: No such file or directory
